Traceback (most recent call last):
  File "/home/chadwiley/research/wofs_40dbz/wofs_ml/data_creator/data_2d_creator.py", line 46, in <module>
    extract_ex_data(examples_path_2020,'2020')
  File "/home/chadwiley/research/wofs_40dbz/wofs_ml/data_creator/data_2d_helper.py", line 132, in extract_ex_data
    out_ds = xr.Dataset(data_vars)
  File "/home/chadwiley/miniconda3/envs/tf/lib/python3.10/site-packages/xarray/core/dataset.py", line 604, in __init__
    variables, coord_names, dims, indexes, _ = merge_data_and_coords(
  File "/home/chadwiley/miniconda3/envs/tf/lib/python3.10/site-packages/xarray/core/merge.py", line 575, in merge_data_and_coords
    return merge_core(
  File "/home/chadwiley/miniconda3/envs/tf/lib/python3.10/site-packages/xarray/core/merge.py", line 761, in merge_core
    dims = calculate_dimensions(variables)
  File "/home/chadwiley/miniconda3/envs/tf/lib/python3.10/site-packages/xarray/core/variable.py", line 3208, in calculate_dimensions
    raise ValueError(
ValueError: conflicting sizes for dimension 'lat': length 128 on 'mrms' and length 18 on {'n_samples': 'comp_dz_max', 'lat': 'comp_dz_max', 'lon': 'comp_dz_max'}
slurmstepd: error: acct_gather_profile/influxdb _send_data: curl_easy_perform failed to send data (discarded). Reason: Couldn't resolve host name
