Traceback (most recent call last):
  File "/home/chadwiley/miniconda3/envs/tf/lib/python3.10/site-packages/xarray/core/dataset.py", line 1339, in _construct_dataarray
    variable = self._variables[name]
KeyError: 'dz_cress'

During handling of the above exception, another exception occurred:

Traceback (most recent call last):
  File "/home/chadwiley/research/wofs_40dbz/wofs_ml/data_creator/data_2d_creator.py", line 24, in <module>
    extract_ex_data(examples_path_2017,'2017-2018')
  File "/home/chadwiley/research/wofs_40dbz/wofs_ml/data_creator/data_2d_helper.py", line 111, in extract_ex_data
    mrms.append(cur_file['dz_cress'][i])
  File "/home/chadwiley/miniconda3/envs/tf/lib/python3.10/site-packages/xarray/core/dataset.py", line 1430, in __getitem__
    return self._construct_dataarray(key)
  File "/home/chadwiley/miniconda3/envs/tf/lib/python3.10/site-packages/xarray/core/dataset.py", line 1341, in _construct_dataarray
    _, name, variable = _get_virtual_variable(self._variables, name, self.dims)
  File "/home/chadwiley/miniconda3/envs/tf/lib/python3.10/site-packages/xarray/core/dataset.py", line 177, in _get_virtual_variable
    raise KeyError(key)
KeyError: 'dz_cress'
slurmstepd: error: acct_gather_profile/influxdb _send_data: curl_easy_perform failed to send data (discarded). Reason: Couldn't resolve host name
