Traceback (most recent call last):
  File "/home/chadwiley/research/wofs_40dbz/wofs_ml/data_creator/data_3d_creator.py", line 63, in <module>
    wofs_probs = xr.concat([wofs_probs,cur_file],dim ='n_samples')
  File "/home/chadwiley/miniconda3/envs/tf/lib/python3.10/site-packages/xarray/core/concat.py", line 243, in concat
    return _dataset_concat(
  File "/home/chadwiley/miniconda3/envs/tf/lib/python3.10/site-packages/xarray/core/concat.py", line 466, in _dataset_concat
    align(*datasets, join=join, copy=False, exclude=[dim], fill_value=fill_value)
  File "/home/chadwiley/miniconda3/envs/tf/lib/python3.10/site-packages/xarray/core/alignment.py", line 772, in align
    aligner.align()
  File "/home/chadwiley/miniconda3/envs/tf/lib/python3.10/site-packages/xarray/core/alignment.py", line 560, in align
    self.assert_unindexed_dim_sizes_equal()
  File "/home/chadwiley/miniconda3/envs/tf/lib/python3.10/site-packages/xarray/core/alignment.py", line 459, in assert_unindexed_dim_sizes_equal
    raise ValueError(
ValueError: cannot reindex or align along dimension 'lat' because of conflicting dimension sizes: {256, 320}
slurmstepd: error: acct_gather_profile/influxdb _send_data: curl_easy_perform failed to send data (discarded). Reason: Couldn't resolve host name
